<?xml version="1.0" encoding="utf-8"?>
<!-- This URDF was automatically created by SolidWorks to URDF Exporter! Originally created by Stephen Brawner (brawner@gmail.com) 
     Commit Version: 1.6.0-4-g7f85cfe  Build Version: 1.6.7995.38578
     For more information, please see http://wiki.ros.org/sw_urdf_exporter -->
<robot
  name="arm">
  <link
    name="0">
    <inertial>
      <origin
        xyz="2.0817E-17 -2.0817E-17 0.031"
        rpy="0 0 0" />
      <mass
        value="1.22" />
      <inertia
        ixx="0.00081006"
        ixy="-2.421E-19"
        ixz="1.1066E-18"
        iyy="0.00036678"
        iyz="-5.5281E-19"
        izz="0.0011734" />
    </inertial>
    <visual>
      <origin
        xyz="0 0 0"
        rpy="0 0 0" />
      <geometry>
        <mesh
          filename="package://arm/meshes/0.STL" />
      </geometry>
      <material
        name="">
        <color
          rgba="0.75294 0.75294 0.75294 1" />
      </material>
    </visual>
    <collision>
      <origin
        xyz="0 0 0"
        rpy="0 0 0" />
      <geometry>
        <mesh
          filename="package://arm/meshes/0.STL" />
      </geometry>
    </collision>
  </link>
  <link
    name="1">
    <inertial>
      <origin
        xyz="-0.00051492 -0.00324 -0.005"
        rpy="0 0 0" />
      <mass
        value="1.177" />
      <inertia
        ixx="0.00023276"
        ixy="2.7142E-07"
        ixz="5.7972E-07"
        iyy="0.00037559"
        iyz="3.7631E-09"
        izz="0.00017771" />
    </inertial>
    <visual>
      <origin
        xyz="0 0 0"
        rpy="0 0 0" />
      <geometry>
        <mesh
          filename="package://arm/meshes/1.STL" />
      </geometry>
      <material
        name="">
        <color
          rgba="0.75294 0.75294 0.75294 1" />
      </material>
    </visual>
    <collision>
      <origin
        xyz="0 0 0"
        rpy="0 0 0" />
      <geometry>
        <mesh
          filename="package://arm/meshes/1.STL" />
      </geometry>
    </collision>
  </link>
  <joint
    name="1"
    type="revolute">
    <origin
      xyz="0 0 0.1281"
      rpy="0 0 0" />
    <parent
      link="0" />
    <child
      link="1" />
    <axis
      xyz="0 0 1" />
    <limit
      lower="-3.14"
      upper="3.14"
      effort="60"
      velocity="17" />
  </joint>
  <link
    name="2">
    <inertial>
      <origin
        xyz="0.276 -0.0116 0"
        rpy="0 0 0" />
      <mass
        value="1.315" />
      <inertia
        ixx="0.00065622"
        ixy="2.0593E-05"
        ixz="1.0253E-06"
        iyy="0.0061131"
        iyz="1.3185E-07"
        izz="0.0059544" />
    </inertial>
    <visual>
      <origin
        xyz="0 0 0"
        rpy="0 0 0" />
      <geometry>
        <mesh
          filename="package://arm/meshes/2.STL" />
      </geometry>
      <material
        name="">
        <color
          rgba="0.75294 0.75294 0.75294 1" />
      </material>
    </visual>
    <collision>
      <origin
        xyz="0 0 0"
        rpy="0 0 0" />
      <geometry>
        <mesh
          filename="package://arm/meshes/2.STL" />
      </geometry>
    </collision>
  </link>
  <joint
    name="2"
    type="revolute">
    <origin
      xyz="0 0 0"
      rpy="-1.5708 0 3.1397" />
    <parent
      link="1" />
    <child
      link="2" />
    <axis
      xyz="0 0 1" />
    <limit
      lower="-3.14"
      upper="3.14"
      effort="60"
      velocity="17" />
  </joint>
  <link
    name="3">
    <inertial>
      <origin
        xyz="0.204 0.0195 0.00036064"
        rpy="0 0 0" />
      <mass
        value="0.86" />
      <inertia
        ixx="0.00054357"
        ixy="-7.5282E-05"
        ixz="-1.8599E-06"
        iyy="0.0037543"
        iyz="2.4044E-07"
        izz="0.003688" />
    </inertial>
    <visual>
      <origin
        xyz="0 0 0"
        rpy="0 0 0" />
      <geometry>
        <mesh
          filename="package://arm/meshes/3.STL" />
      </geometry>
      <material
        name="">
        <color
          rgba="0.75294 0.75294 0.75294 1" />
      </material>
    </visual>
    <collision>
      <origin
        xyz="0 0 0"
        rpy="0 0 0" />
      <geometry>
        <mesh
          filename="package://arm/meshes/3.STL" />
      </geometry>
    </collision>
  </link>
  <joint
    name="3"
    type="revolute">
    <origin
      xyz="0.37425 0 0"
      rpy="0 0 -2.8166" />
    <parent
      link="2" />
    <child
      link="3" />
    <axis
      xyz="0 0 1" />
    <limit
      lower="-3.14"
      upper="3.14"
      effort="30"
      velocity="15" />
  </joint>
  <link
    name="4">
    <inertial>
      <origin
        xyz="0.0675 0.0574 -0.0038986"
        rpy="0 0 0" />
      <mass
        value="0.407" />
      <inertia
        ixx="2.5844E-05"
        ixy="-8.9302E-06"
        ixz="3.3796E-07"
        iyy="4.2862E-05"
        iyz="3.2589E-07"
        izz="4.3837E-05" />
    </inertial>
    <visual>
      <origin
        xyz="0 0 0"
        rpy="0 0 0" />
      <geometry>
        <mesh
          filename="package://arm/meshes/4.STL" />
      </geometry>
      <material
        name="">
        <color
          rgba="0.75294 0.75294 0.75294 1" />
      </material>
    </visual>
    <collision>
      <origin
        xyz="0 0 0"
        rpy="0 0 0" />
      <geometry>
        <mesh
          filename="package://arm/meshes/4.STL" />
      </geometry>
    </collision>
  </link>
  <joint
    name="4"
    type="revolute">
    <origin
      xyz="0.30395 0.00032772 0"
      rpy="0 0 -0.3307" />
    <parent
      link="3" />
    <child
      link="4" />
    <axis
      xyz="0 0 1" />
    <limit
      lower="-3.14"
      upper="3.14"
      effort="17"
      velocity="15" />
  </joint>
  <link
    name="5">
    <inertial>
      <origin
        xyz="0.00043477 0.0038 0.0027"
        rpy="0 0 0" />
      <mass
        value="0.35" />
      <inertia
        ixx="1.1674E-05"
        ixy="7.7591E-09"
        ixz="2.4776E-10"
        iyy="1.5756E-05"
        iyz="1.3036E-07"
        izz="1.0894E-05" />
    </inertial>
    <visual>
      <origin
        xyz="0 0 0"
        rpy="0 0 0" />
      <geometry>
        <mesh
          filename="package://arm/meshes/5.STL" />
      </geometry>
      <material
        name="">
        <color
          rgba="0.75294 0.75294 0.75294 1" />
      </material>
    </visual>
    <collision>
      <origin
        xyz="0 0 0"
        rpy="0 0 0" />
      <geometry>
        <mesh
          filename="package://arm/meshes/5.STL" />
      </geometry>
    </collision>
  </link>
  <joint
    name="5"
    type="revolute">
    <origin
      xyz="0.080376 0.0018417 -0.0020003"
      rpy="-1.5708 -1.5689 0.0056773" />
    <parent
      link="4" />
    <child
      link="5" />
    <axis
      xyz="0 0 1" />
    <limit
      lower="-3.14"
      upper="3.14"
      effort="17"
      velocity="15" />
  </joint>
  <link
    name="6">
    <inertial>
      <origin
        xyz="-0.001629 -1.2741E-06 0.044"
        rpy="0 0 0" />
      <mass
        value="0.32342" />
      <inertia
        ixx="1.2001E-05"
        ixy="3.9843E-06"
        ixz="4.4272E-09"
        iyy="0.00013376"
        iyz="1.445E-09"
        izz="0.00014443" />
    </inertial>
    <visual>
      <origin
        xyz="0 0 0"
        rpy="0 0 0" />
      <geometry>
        <mesh
          filename="package://arm/meshes/6.STL" />
      </geometry>
      <material
        name="">
        <color
          rgba="1 1 1 1" />
      </material>
    </visual>
    <collision>
      <origin
        xyz="0 0 0"
        rpy="0 0 0" />
      <geometry>
        <mesh
          filename="package://arm/meshes/6.STL" />
      </geometry>
    </collision>
  </link>
  <joint
    name="6"
    type="revolute">
    <origin
      xyz="0.0020919 0.029927 0"
      rpy="-1.5708 0 -0.0019006" />
    <parent
      link="5" />
    <child
      link="6" />
    <axis
      xyz="0 0 1" />
    <limit
      lower="-3.14"
      upper="3.14"
      effort="17"
      velocity="15" />
  </joint>
  <link
    name="7-1">
    <inertial>
      <origin
        xyz="0.015576 0.0075042 0.027703"
        rpy="0 0 0" />
      <mass
        value="0.019078" />
      <inertia
        ixx="7.0719E-06"
        ixy="-4.5401E-07"
        ixz="4.6553E-07"
        iyy="4.2036E-06"
        iyz="3.5257E-07"
        izz="5.198E-06" />
    </inertial>
    <visual>
      <origin
        xyz="0 0 0"
        rpy="0 0 0" />
      <geometry>
        <mesh
          filename="package://arm/meshes/7-1.STL" />
      </geometry>
      <material
        name="">
        <color
          rgba="0.3098 0.3098 0.3098 1" />
      </material>
    </visual>
    <collision>
      <origin
        xyz="0 0 0"
        rpy="0 0 0" />
      <geometry>
        <mesh
          filename="package://arm/meshes/7-1.STL" />
      </geometry>
    </collision>
  </link>
  <joint
    name="7"
    type="prismatic">
    <origin
      xyz="-0.0016279 0 0.064947"
      rpy="0 0 -0.048473" />
    <parent
      link="6" />
    <child
      link="7-1" />
    <axis
      xyz="-1 0 0" />
    <limit
      lower="0"
      upper="0.1"
      effort="1"
      velocity="0.1" />
  </joint>
  <link
    name="7-2">
    <inertial>
      <origin
        xyz="-0.015696 0.010047 0.027253"
        rpy="0 0 0" />
      <mass
        value="0.019828" />
      <inertia
        ixx="8.8108E-06"
        ixy="6.0965E-07"
        ixz="-4.6817E-07"
        iyy="4.2803E-06"
        iyz="4.5065E-07"
        izz="6.9965E-06" />
    </inertial>
    <visual>
      <origin
        xyz="0 0 0"
        rpy="0 0 0" />
      <geometry>
        <mesh
          filename="package://arm/meshes/7-2.STL" />
      </geometry>
      <material
        name="">
        <color
          rgba="0.33333 0.33333 0.33333 1" />
      </material>
    </visual>
    <collision>
      <origin
        xyz="0 0 0"
        rpy="0 0 0" />
      <geometry>
        <mesh
          filename="package://arm/meshes/7-2.STL" />
      </geometry>
    </collision>
  </link>
  <joint
    name="8"
    type="prismatic">
    <origin
      xyz="-0.0016279 0 0.064947"
      rpy="0 0 -0.048473" />
    <parent
      link="6" />
    <child
      link="7-2" />
    <axis
      xyz="-1 0 0" />
    <limit
      lower="0"
      upper="0.1"
      effort="1"
      velocity="0.1" />
  </joint>
</robot>